Task exception was never retrieved
future: <Task finished name='Task-651' coro=<Client.handle_updates() done, defined at /home/ubuntu/.local/lib/python3.13/site-packages/pyrogram/client.py:535> exception=ValueError('Peer id invalid: -1002727115068')>
Traceback (most recent call last):
  File "/home/ubuntu/.local/lib/python3.13/site-packages/pyrogram/methods/advanced/resolve_peer.py", line 62, in resolve_peer
    return await self.storage.get_peer_by_id(peer_id)
           ^^^^^^^^^^^^^^^^^^^^^^^^^^^^^^^^^^^^^^^^^^
  File "/home/ubuntu/.local/lib/python3.13/site-packages/pyrogram/storage/sqlite_storage.py", line 142, in get_peer_by_id
    raise KeyError(f"ID not found: {peer_id}")
KeyError: 'ID not found: -1002727115068'

During handling of the above exception, another exception occurred:

Traceback (most recent call last):
  File "/home/ubuntu/.local/lib/python3.13/site-packages/pyrogram/client.py", line 569, in handle_updates
    channel=await self.resolve_peer(utils.get_channel_id(channel_id)),
            ^^^^^^^^^^^^^^^^^^^^^^^^^^^^^^^^^^^^^^^^^^^^^^^^^^^^^^^^^
  File "/home/ubuntu/.local/lib/python3.13/site-packages/pyrogram/methods/advanced/resolve_peer.py", line 89, in resolve_peer
    peer_type = utils.get_peer_type(peer_id)
  File "/home/ubuntu/.local/lib/python3.13/site-packages/pyrogram/utils.py", line 246, in get_peer_type
    raise ValueError(f"Peer id invalid: {peer_id}")
ValueError: Peer id invalid: -1002727115068
Task exception was never retrieved
future: <Task finished name='Task-652' coro=<Client.handle_updates() done, defined at /home/ubuntu/.local/lib/python3.13/site-packages/pyrogram/client.py:535> exception=ValueError('Peer id invalid: -1002727115068')>
Traceback (most recent call last):
  File "/home/ubuntu/.local/lib/python3.13/site-packages/pyrogram/methods/advanced/resolve_peer.py", line 62, in resolve_peer
    return await self.storage.get_peer_by_id(peer_id)
           ^^^^^^^^^^^^^^^^^^^^^^^^^^^^^^^^^^^^^^^^^^
  File "/home/ubuntu/.local/lib/python3.13/site-packages/pyrogram/storage/sqlite_storage.py", line 142, in get_peer_by_id
    raise KeyError(f"ID not found: {peer_id}")
KeyError: 'ID not found: -1002727115068'

During handling of the above exception, another exception occurred:

Traceback (most recent call last):
  File "/home/ubuntu/.local/lib/python3.13/site-packages/pyrogram/client.py", line 569, in handle_updates
    channel=await self.resolve_peer(utils.get_channel_id(channel_id)),
            ^^^^^^^^^^^^^^^^^^^^^^^^^^^^^^^^^^^^^^^^^^^^^^^^^^^^^^^^^
  File "/home/ubuntu/.local/lib/python3.13/site-packages/pyrogram/methods/advanced/resolve_peer.py", line 89, in resolve_peer
    peer_type = utils.get_peer_type(peer_id)
  File "/home/ubuntu/.local/lib/python3.13/site-packages/pyrogram/utils.py", line 246, in get_peer_type
    raise ValueError(f"Peer id invalid: {peer_id}")
ValueError: Peer id invalid: -1002727115068
Task exception was never retrieved
future: <Task finished name='Task-664' coro=<Client.handle_updates() done, defined at /home/ubuntu/.local/lib/python3.13/site-packages/pyrogram/client.py:535> exception=ValueError('Peer id invalid: -1002727115068')>
Traceback (most recent call last):
  File "/home/ubuntu/.local/lib/python3.13/site-packages/pyrogram/methods/advanced/resolve_peer.py", line 62, in resolve_peer
    return await self.storage.get_peer_by_id(peer_id)
           ^^^^^^^^^^^^^^^^^^^^^^^^^^^^^^^^^^^^^^^^^^
  File "/home/ubuntu/.local/lib/python3.13/site-packages/pyrogram/storage/sqlite_storage.py", line 142, in get_peer_by_id
    raise KeyError(f"ID not found: {peer_id}")
KeyError: 'ID not found: -1002727115068'

During handling of the above exception, another exception occurred:

Traceback (most recent call last):
  File "/home/ubuntu/.local/lib/python3.13/site-packages/pyrogram/client.py", line 569, in handle_updates
    channel=await self.resolve_peer(utils.get_channel_id(channel_id)),
            ^^^^^^^^^^^^^^^^^^^^^^^^^^^^^^^^^^^^^^^^^^^^^^^^^^^^^^^^^
  File "/home/ubuntu/.local/lib/python3.13/site-packages/pyrogram/methods/advanced/resolve_peer.py", line 89, in resolve_peer
    peer_type = utils.get_peer_type(peer_id)
  File "/home/ubuntu/.local/lib/python3.13/site-packages/pyrogram/utils.py", line 246, in get_peer_type
    raise ValueError(f"Peer id invalid: {peer_id}")
ValueError: Peer id invalid: -1002727115068
Task exception was never retrieved
future: <Task finished name='Task-669' coro=<Client.handle_updates() done, defined at /home/ubuntu/.local/lib/python3.13/site-packages/pyrogram/client.py:535> exception=ValueError('Peer id invalid: -1002727115068')>
Traceback (most recent call last):
  File "/home/ubuntu/.local/lib/python3.13/site-packages/pyrogram/methods/advanced/resolve_peer.py", line 62, in resolve_peer
    return await self.storage.get_peer_by_id(peer_id)
           ^^^^^^^^^^^^^^^^^^^^^^^^^^^^^^^^^^^^^^^^^^
  File "/home/ubuntu/.local/lib/python3.13/site-packages/pyrogram/storage/sqlite_storage.py", line 142, in get_peer_by_id
    raise KeyError(f"ID not found: {peer_id}")
KeyError: 'ID not found: -1002727115068'

During handling of the above exception, another exception occurred:

Traceback (most recent call last):
  File "/home/ubuntu/.local/lib/python3.13/site-packages/pyrogram/client.py", line 569, in handle_updates
    channel=await self.resolve_peer(utils.get_channel_id(channel_id)),
            ^^^^^^^^^^^^^^^^^^^^^^^^^^^^^^^^^^^^^^^^^^^^^^^^^^^^^^^^^
  File "/home/ubuntu/.local/lib/python3.13/site-packages/pyrogram/methods/advanced/resolve_peer.py", line 89, in resolve_peer
    peer_type = utils.get_peer_type(peer_id)
  File "/home/ubuntu/.local/lib/python3.13/site-packages/pyrogram/utils.py", line 246, in get_peer_type
    raise ValueError(f"Peer id invalid: {peer_id}")
ValueError: Peer id invalid: -1002727115068
Task exception was never retrieved
future: <Task finished name='Task-674' coro=<Client.handle_updates() done, defined at /home/ubuntu/.local/lib/python3.13/site-packages/pyrogram/client.py:535> exception=ValueError('Peer id invalid: -1002727115068')>
Traceback (most recent call last):
  File "/home/ubuntu/.local/lib/python3.13/site-packages/pyrogram/methods/advanced/resolve_peer.py", line 62, in resolve_peer
    return await self.storage.get_peer_by_id(peer_id)
           ^^^^^^^^^^^^^^^^^^^^^^^^^^^^^^^^^^^^^^^^^^
  File "/home/ubuntu/.local/lib/python3.13/site-packages/pyrogram/storage/sqlite_storage.py", line 142, in get_peer_by_id
    raise KeyError(f"ID not found: {peer_id}")
KeyError: 'ID not found: -1002727115068'

During handling of the above exception, another exception occurred:

Traceback (most recent call last):
  File "/home/ubuntu/.local/lib/python3.13/site-packages/pyrogram/client.py", line 569, in handle_updates
    channel=await self.resolve_peer(utils.get_channel_id(channel_id)),
            ^^^^^^^^^^^^^^^^^^^^^^^^^^^^^^^^^^^^^^^^^^^^^^^^^^^^^^^^^
  File "/home/ubuntu/.local/lib/python3.13/site-packages/pyrogram/methods/advanced/resolve_peer.py", line 89, in resolve_peer
    peer_type = utils.get_peer_type(peer_id)
  File "/home/ubuntu/.local/lib/python3.13/site-packages/pyrogram/utils.py", line 246, in get_peer_type
    raise ValueError(f"Peer id invalid: {peer_id}")
ValueError: Peer id invalid: -1002727115068
